Workbook

Sheet INDEX
B3: NAME | C3: ANURAG KUMAR
B4: Roll No. | C4: 25PGDMFM012
B5: College Name | C5: FIIB
B6: Company Name | C6: HDFC Life

Sheet RSI
B1: PRIVATE BANKS
B3: BUY | H3: SELL
B4: Q1 | H4: Q1
B5: SYMBOL | C5: BACKTEST P&L | D5: TOTAL NUMBER OF TRADES | E5: NUMBER OF WINS | F5: NUMBER OF LOSSES | H5: SYMBOL | I5: BACKTEST P&L | J5: TOTAL NUMBER OF TRADES | K5: NUMBER OF WINS | L5: NUMBER OF LOSSES
B6: HDFC BANK | C6: -666.9 | D6: 29 | E6: 13 | F6: =D6-E6 -> 16 | H6: HDFC BANK | I6: -297.85 | J6: 47 | K6: 26 | L6: =J6-K6 -> 21
B7: AXIS BANK | C7: 1022.96 | D7: 41 | E7: 20 | F7: =D7-E7 -> 21 | H7: AXIS BANK | I7: 63.94 | J7: 50 | K7: 26 | L7: =J7-K7 -> 24
B8: KOTAKBANK | C8: 1037.6 | D8: 39 | E8: 20 | F8: =D8-E8 -> 19 | H8: KOTAKBANK | I8: 250.29 | J8: 40 | K8: 23 | L8: =J8-K8 -> 17
B9: YES BANK | C9: 44.98 | D9: 41 | E9: 16 | F9: =D9-E9 -> 25 | H9: YES BANK | I9: 304.58 | J9: 50 | K9: 21 | L9: =J9-K9 -> 29
B10: AUB BANK | C10: -327.45 | D10: 33 | E10: 12 | F10: =D10-E10 -> 21 | H10: AUB BANK | I10: -1483.1 | J10: 57 | K10: 24 | L10: =J10-K10 -> 33
B11: INDUSINDBK | C11: 233.6 | D11: 36 | E11: 14 | F11: =D11-E11 -> 22 | H11: INDUSINDBK | I11: 892.9 | J11: 49 | K11: 23 | L11: =J11-K11 -> 26
B12: ICICI BANK | C12: 267.25 | D12: 34 | E12: 18 | F12: =D12-E12 -> 16 | H12: ICICI BANK | I12: 285.45 | J12: 42 | K12: 24 | L12: =J12-K12 -> 18
B13: IDFCFIRSTB | C13: 606.15 | D13: 36 | E13: 19 | F13: =D13-E13 -> 17 | H13: IDFCFIRSTB | I13: -1019.94 | J13: 51 | K13: 24 | L13: =J13-K13 -> 27
B14: BANKBARODA | C14: -1191.36 | D14: 38 | E14: 15 | F14: =D14-E14 -> 23 | H14: BANKBARODA | I14: -486.61 | J14: 49 | K14: 21 | L14: =J14-K14 -> 28
B15: UNIONBANK | C15: 575.86 | D15: 37 | E15: 17 | F15: =D15-E15 -> 20 | H15: UNIONBANK | I15: -493.67 | J15: 58 | K15: 27 | L15: =J15-K15 -> 31
B16: FEDERAL BANK | C16: 734.6 | D16: 43 | E16: 21 | F16: =D16-E16 -> 22 | H16: FEDERAL BANK | I16: 581.93 | J16: 54 | K16: 27 | L16: =J16-K16 -> 27
D17: =SUM(D6:D16) -> 407 | E17: =SUM(E6:E16) -> 185 | F17: =SUM(F6:F16) -> 222 | J17: =SUM(J6:J16) -> 547 | K17: =SUM(K6:K16) -> 266 | L17: =SUM(L6:L16) -> 281
B18: Q2 | H18: Q2
B19: SYMBOL | C19: BACKTEST P&L | D19: TOTAL NUMBER OF TRADES | E19: NUMBER OF WINS | F19: NUMBER OF LOSSES | H19: SYMBOL | I19: BACKTEST P&L | J19: TOTAL NUMBER OF TRADES | K19: NUMBER OF WINS | L19: NUMBER OF LOSSES
B20: HDFC BANK | C20: -312.4 | D20: 39 | E20: 15 | F20: =D20-E20 -> 24 | H20: HDFC BANK | I20: 66.5 | J20: 31 | K20: 20 | L20: =J20-K20 -> 11
B21: AXIS BANK | C21: 90.35 | D21: 38 | E21: 21 | F21: =D21-E21 -> 17 | H21: AXIS BANK | I21: 986.35 | J21: 36 | K21: 22 | L21: =J21-K21 -> 14
B22: KOTAKBANK | C22: -470 | D22: 39 | E22: 17 | F22: =D22-E22 -> 22 | H22: KOTAKBANK | I22: 1345.65 | J22: 36 | K22: 22 | L22: =J22-K22 -> 14
B23: YES BANK | C23: 310.31 | D23: 40 | E23: 20 | F23: =D23-E23 -> 20 | H23: YES BANK | I23: 546.75 | J23: 47 | K23: 27 | L23: =J23-K23 -> 20
B24: AUB BANK | C24: -221.4 | D24: 56 | E24: 22 | F24: =D24-E24 -> 34 | H24: AUB BANK | I24: 243.15 | J24: 47 | K24: 21 | L24: =J24-K24 -> 26
B25: INDUSINDBK | C25: -854.15 | D25: 54 | E25: 20 | F25: =D25-E25 -> 34 | H25: INDUSINDBK | I25: 1451.05 | J25: 38 | K25: 22 | L25: =J25-K25 -> 16
B26: ICICI BANK | C26: 470.85 | D26: 37 | E26: 21 | F26: =D26-E26 -> 16 | H26: ICICI BANK | I26: 553.25 | J26: 32 | K26: 20 | L26: =J26-K26 -> 12
B27: IDFCFIRSTB | C27: -1052.69 | D27: 52 | E27: 19 | F27: =D27-E27 -> 33 | H27: IDFCFIRSTB | I27: 1408.1 | J27: 34 | K27: 19 | L27: =J27-K27 -> 15
B28: BANKBARODA | C28: -674.23 | D28: 45 | E28: 18 | F28: =D28-E28 -> 27 | H28: BANKBARODA | I28: -61.87 | J28: 52 | K28: 23 | L28: =J28-K28 -> 29
B29: UNIONBANK | C29: 334.65 | D29: 43 | E29: 19 | F29: =D29-E29 -> 24 | H29: UNIONBANK | I29: 26.13 | J29: 50 | K29: 19 | L29: =J29-K29 -> 31
B30: FEDERAL BANK | C30: -1622.52 | D30: 43 | E30: 14 | F30: =D30-E30 -> 29 | H30: FEDERAL BANK | I30: 227.4 | J30: 29 | K30: 17 | L30: =J30-K30 -> 12
D31: =SUM(D20:D30) -> 486 | E31: =SUM(E20:E30) -> 206 | F31: =SUM(F20:F30) -> 280 | J31: =SUM(J20:J30) -> 432 | K31: =SUM(K20:K30) -> 232 | L31: =SUM(L20:L30) -> 200
B32: Q3 | H32: Q3
B33: SYMBOL | C33: BACKTEST P&L | D33: TOTAL NUMBER OF TRADES | E33: NUMBER OF WINS | F33: NUMBER OF LOSSES | H33: SYMBOL | I33: BACKTEST P&L | J33: TOTAL NUMBER OF TRADES | K33: NUMBER OF WINS | L33: NUMBER OF LOSSES
B34: HDFC BANK | C34: 392.85 | D34: 33 | E34: 22 | F34: =D34-E34 -> 11 | H34: HDFC BANK | I34: 146.25 | J34: 34 | K34: 20 | L34: =J34-K34 -> 14
B35: AXIS BANK | C35: -499.04 | D35: 31 | E35: 15 | F35: =D35-E35 -> 16 | H35: AXIS BANK | I35: -277.5 | J35: 43 | K35: 22 | L35: =J35-K35 -> 21
B36: KOTAKBANK | C36: 520.7 | D36: 31 | E36: 13 | F36: =D36-E36 -> 18 | H36: KOTAKBANK | I36: 326.1 | J36: 43 | K36: 25 | L36: =J36-K36 -> 18
B37: YES BANK | C37: -1580.8 | D37: 49 | E37: 21 | F37: =D37-E37 -> 28 | H37: YES BANK | I37: 805.21 | J37: 41 | K37: 24 | L37: =J37-K37 -> 17
B38: AUB BANK | C38: 1157.35 | D38: 35 | E38: 19 | F38: =D38-E38 -> 16 | H38: AUB BANK | I38: -860.05 | J38: 53 | K38: 24 | L38: =J38-K38 -> 29
B39: INDUSINDBK | C39: 973.55 | D39: 38 | E39: 20 | F39: =D39-E39 -> 18 | H39: INDUSINDBK | I39: -1748.9 | J39: 47 | K39: 19 | L39: =J39-K39 -> 28
B40: ICICI BANK | C40: -902.29 | D40: 38 | E40: 19 | F40: =D40-E40 -> 19 | H40: ICICI BANK | I40: -1065.9 | J40: 31 | K40: 14 | L40: =J40-K40 -> 17
B41: IDFCFIRSTB | C41: 665.99 | D41: 33 | E41: 18 | F41: =D41-E41 -> 15 | H41: IDFCFIRSTB | I41: -1853.97 | J41: 49 | K41: 18 | L41: =J41-K41 -> 31
...

Sheet Supertrend
B1: PRIVATE BANKS
B3: BUY | H3: SELL
B4: Q1 | H4: Q1
B5: SYMBOL | C5: BACKTEST P&L | D5: TOTAL NUMBER OF TRADES | E5: NUMBER OF WINS | F5: NUMBER OF LOSSES | H5: SYMBOL | I5: BACKTEST P&L | J5: TOTAL NUMBER OF TRADES | K5: NUMBER OF WINS | L5: NUMBER OF LOSSES
B6: HDFC BANK | C6: 16.15 | D6: 46 | E6: 18 | F6: =D6-E6 -> 28 | H6: HDFC BANK | I6: -1505.14 | J6: 47 | K6: 20 | L6: =J6-K6 -> 27
B7: AXIS BANK | C7: 61.05 | D7: 45 | E7: 23 | F7: =D7-E7 -> 22 | H7: AXIS BANK | I7: 1474.84 | J7: 69 | K7: 39 | L7: =J7-K7 -> 30
B8: KOTAKBANK | C8: 686.15 | D8: 51 | E8: 25 | F8: =D8-E8 -> 26 | H8: KOTAKBANK | I8: 263.2 | J8: 56 | K8: 30 | L8: =J8-K8 -> 26
B9: YES BANK | C9: 166.45 | D9: 47 | E9: 20 | F9: =D9-E9 -> 27 | H9: YES BANK | I9: -186.99 | J9: 45 | K9: 22 | L9: =J9-K9 -> 23
B10: AUB BANK | C10: 2179.45 | D10: 46 | E10: 27 | F10: =D10-E10 -> 19 | H10: AUB BANK | I10: 985.25 | J10: 54 | K10: 28 | L10: =J10-K10 -> 26
B11: INDUSINDBK | C11: 860 | D11: 57 | E11: 27 | F11: =D11-E11 -> 30 | H11: INDUSINDBK | I11: -387.64 | J11: 56 | K11: 27 | L11: =J11-K11 -> 29
B12: ICICI BANK | C12: 861.9 | D12: 44 | E12: 28 | F12: =D12-E12 -> 16 | H12: ICICI BANK | I12: -747.64 | J12: 49 | K12: 22 | L12: =J12-K12 -> 27
B13: IDFCFIRSTB | C13: 1961.53 | D13: 48 | E13: 26 | F13: =D13-E13 -> 22 | H13: IDFCFIRSTB | I13: 2318.39 | J13: 47 | K13: 27 | L13: =J13-K13 -> 20
B14: BANKBARODA | C14: 1466.26 | D14: 52 | E14: 29 | F14: =D14-E14 -> 23 | H14: BANKBARODA | I14: 1839.4 | J14: 55 | K14: 29 | L14: =J14-K14 -> 26
B15: UNIONBANK | C15: 2579.08 | D15: 57 | E15: 31 | F15: =D15-E15 -> 26 | H15: UNIONBANK | I15: 661.43 | J15: 55 | K15: 26 | L15: =J15-K15 -> 29
B16: FEDERAL BANK | C16: 2097.47 | D16: 43 | E16: 25 | F16: =D16-E16 -> 18 | H16: FEDERAL BANK | I16: -667.84 | J16: 52 | K16: 26 | L16: =J16-K16 -> 26
D17: =SUM(D6:D16) -> 536 | E17: =SUM(E6:E16) -> 279 | F17: =SUM(F6:F16) -> 257 | J17: =SUM(J6:J16) -> 585 | K17: =SUM(K6:K16) -> 296 | L17: =SUM(L6:L16) -> 289
B18: Q2 | H18: Q2
B19: SYMBOL | C19: BACKTEST P&L | D19: TOTAL NUMBER OF TRADES | E19: NUMBER OF WINS | F19: NUMBER OF LOSSES | H19: SYMBOL | I19: BACKTEST P&L | J19: TOTAL NUMBER OF TRADES | K19: NUMBER OF WINS | L19: NUMBER OF LOSSES
B20: HDFC BANK | C20: -1977.44 | D20: 50 | E20: 19 | F20: =D20-E20 -> 31 | H20: HDFC BANK | I20: 435.54 | J20: 47 | K20: 26 | L20: =J20-K20 -> 21
B21: AXIS BANK | C21: -236.8 | D21: 50 | E21: 25 | F21: =D21-E21 -> 25 | H21: AXIS BANK | I21: -1070.4 | J21: 56 | K21: 26 | L21: =J21-K21 -> 30
B22: KOTAKBANK | C22: -308.49 | D22: 54 | E22: 25 | F22: =D22-E22 -> 29 | H22: KOTAKBANK | I22: 433.74 | J22: 48 | K22: 21 | L22: =J22-K22 -> 27
B23: YES BANK | C23: 1039.57 | D23: 44 | E23: 21 | F23: =D23-E23 -> 23 | H23: YES BANK | I23: 1330.07 | J23: 45 | K23: 28 | L23: =J23-K23 -> 17
B24: AUB BANK | C24: 887.29 | D24: 50 | E24: 25 | F24: =D24-E24 -> 25 | H24: AUB BANK | I24: 1846.34 | J24: 52 | K24: 27 | L24: =J24-K24 -> 25
B25: INDUSINDBK | C25: 205.75 | D25: 52 | E25: 22 | F25: =D25-E25 -> 30 | H25: INDUSINDBK | I25: 2292.39 | J25: 55 | K25: 33 | L25: =J25-K25 -> 22
B26: ICICI BANK | C26: -306.44 | D26: 49 | E26: 24 | F26: =D26-E26 -> 25 | H26: ICICI BANK | I26: 190.3 | J26: 43 | K26: 23 | L26: =J26-K26 -> 20
B27: IDFCFIRSTB | C27: -3234.27 | D27: 58 | E27: 18 | F27: =D27-E27 -> 40 | H27: IDFCFIRSTB | I27: 1907.86 | J27: 49 | K27: 30 | L27: =J27-K27 -> 19
B28: BANKBARODA | C28: -1124.88 | D28: 52 | E28: 19 | F28: =D28-E28 -> 33 | H28: BANKBARODA | I28: 1584.35 | J28: 52 | K28: 33 | L28: =J28-K28 -> 19
B29: UNIONBANK | C29: -994.86 | D29: 55 | E29: 22 | F29: =D29-E29 -> 33 | H29: UNIONBANK | I29: 687.1 | J29: 56 | K29: 29 | L29: =J29-K29 -> 27
B30: FEDERAL BANK | C30: -1513.78 | D30: 51 | E30: 18 | F30: =D30-E30 -> 33 | H30: FEDERAL BANK | I30: 1158.74 | J30: 51 | K30: 29 | L30: =J30-K30 -> 22
D31: =SUM(D20:D30) -> 565 | E31: =SUM(E20:E30) -> 238 | F31: =SUM(F20:F30) -> 327 | J31: =SUM(J20:J30) -> 554 | K31: =SUM(K20:K30) -> 305 | L31: =SUM(L20:L30) -> 249
B32: Q3 | H32: Q3
B33: SYMBOL | C33: BACKTEST P&L | D33: TOTAL NUMBER OF TRADES | E33: NUMBER OF WINS | F33: NUMBER OF LOSSES | H33: SYMBOL | I33: BACKTEST P&L | J33: TOTAL NUMBER OF TRADES | K33: NUMBER OF WINS | L33: NUMBER OF LOSSES
B34: HDFC BANK | C34: -504.64 | D34: 48 | E34: 21 | F34: =D34-E34 -> 27 | H34: HDFC BANK | I34: 364.94 | J34: 46 | K34: 26 | L34: =J34-K34 -> 20
B35: AXIS BANK | C35: -513.1 | D35: 49 | E35: 26 | F35: =D35-E35 -> 23 | H35: AXIS BANK | I35: 895.24 | J35: 50 | K35: 29 | L35: =J35-K35 -> 21
B36: KOTAKBANK | C36: -136.85 | D36: 51 | E36: 21 | F36: =D36-E36 -> 30 | H36: KOTAKBANK | I36: -147.54 | J36: 45 | K36: 25 | L36: =J36-K36 -> 20
B37: YES BANK | C37: 1285.57 | D37: 42 | E37: 22 | F37: =D37-E37 -> 20 | H37: YES BANK | I37: 2532.84 | J37: 39 | K37: 24 | L37: =J37-K37 -> 15
B38: AUB BANK | C38: 1099.05 | D38: 47 | E38: 26 | F38: =D38-E38 -> 21 | H38: AUB BANK | I38: -1588.8 | J38: 49 | K38: 24 | L38: =J38-K38 -> 25
B39: INDUSINDBK | C39: -326.69 | D39: 56 | E39: 24 | F39: =D39-E39 -> 32 | H39: INDUSINDBK | I39: -713.75 | J39: 52 | K39: 19 | L39: =J39-K39 -> 33
B40: ICICI BANK | C40: 534.2 | D40: 40 | E40: 19 | F40: =D40-E40 -> 21 | H40: ICICI BANK | I40: 119.94 | J40: 40 | K40: 18 | L40: =J40-K40 -> 22
B41: IDFCFIRSTB | C41: -103.88 | D41: 55 | E41: 27 | F41: =D41-E41 -> 28 | H41: IDFCFIRSTB | I41: -1238.8 | J41: 54 | K41: 27 | L41: =J41-K41 -> 27
...

Sheet VWAP
B1: PRIVATE BANKS
B3: BUY | H3: SELL
B4: Q1 | H4: Q1
B5: SYMBOL | C5: BACKTEST P&L | D5: TOTAL NUMBER OF TRADES | E5: NUMBER OF WINS | F5: NUMBER OF LOSSES | H5: SYMBOL | I5: BACKTEST P&L | J5: TOTAL NUMBER OF TRADES | K5: NUMBER OF WINS | L5: NUMBER OF LOSSES
B6: HDFC BANK | C6: 10.65 | D6: 63 | E6: 28 | F6: =D6-E6 -> 35 | H6: HDFC BANK | I6: -438 | J6: 69 | K6: 32 | L6: =J6-K6 -> 37
B7: AXIS BANK | C7: -55.7 | D7: 68 | E7: 31 | F7: =D7-E7 -> 37 | H7: AXIS BANK | I7: 858.39 | J7: 72 | K7: 26 | L7: =J7-K7 -> 46
B8: KOTAKBANK | C8: -194.9 | D8: 62 | E8: 31 | F8: =D8-E8 -> 31 | H8: KOTAKBANK | I8: 138.79 | J8: 64 | K8: 35 | L8: =J8-K8 -> 29
B9: YES BANK | C9: -806.21 | D9: 67 | E9: 24 | F9: =D9-E9 -> 43 | H9: YES BANK | I9: 975.15 | J9: 71 | K9: 31 | L9: =J9-K9 -> 40
B10: AUB BANK | C10: 747.65 | D10: 76 | E10: 32 | F10: =D10-E10 -> 44 | H10: AUB BANK | I10: -2477.1 | J10: 82 | K10: 31 | L10: =J10-K10 -> 51
B11: INDUSINDBK | C11: 1066.2 | D11: 85 | E11: 37 | F11: =D11-E11 -> 48 | H11: INDUSINDBK | I11: -1574.55 | J11: 89 | K11: 34 | L11: =J11-K11 -> 55
B12: ICICI BANK | C12: -50.25 | D12: 64 | E12: 34 | F12: =D12-E12 -> 30 | H12: ICICI BANK | I12: -614.45 | J12: 65 | K12: 29 | L12: =J12-K12 -> 36
B13: IDFCFIRSTB | C13: 661.98 | D13: 78 | E13: 38 | F13: =D13-E13 -> 40 | H13: IDFCFIRSTB | I13: -2095.86 | J13: 75 | K13: 29 | L13: =J13-K13 -> 46
B14: BANKBARODA | C14: 1767.47 | D14: 76 | E14: 39 | F14: =D14-E14 -> 37 | H14: BANKBARODA | I14: -305.67 | J14: 84 | K14: 36 | L14: =J14-K14 -> 48
B15: UNIONBANK | C15: 1023.12 | D15: 86 | E15: 39 | F15: =D15-E15 -> 47 | H15: UNIONBANK | I15: 173.05 | J15: 98 | K15: 40 | L15: =J15-K15 -> 58
B16: FEDERAL BANK | C16: -126.55 | D16: 70 | E16: 34 | F16: =D16-E16 -> 36 | H16: FEDERAL BANK | I16: -147.52 | J16: 73 | K16: 28 | L16: =J16-K16 -> 45
D17: =SUM(D6:D16) -> 795 | E17: =SUM(E6:E16) -> 367 | F17: =SUM(F6:F16) -> 428 | J17: =SUM(J6:J16) -> 842 | K17: =SUM(K6:K16) -> 351 | L17: =SUM(L6:L16) -> 491
B18: Q2 | H18: Q2
B19: SYMBOL | C19: BACKTEST P&L | D19: TOTAL NUMBER OF TRADES | E19: NUMBER OF WINS | F19: NUMBER OF LOSSES | H19: SYMBOL | I19: BACKTEST P&L | J19: TOTAL NUMBER OF TRADES | K19: NUMBER OF WINS | L19: NUMBER OF LOSSES
B20: HDFC BANK | C20: -1846.8 | D20: 64 | E20: 28 | F20: =D20-E20 -> 36 | H20: HDFC BANK | I20: 1051.84 | J20: 63 | K20: 36 | L20: =J20-K20 -> 27
B21: AXIS BANK | C21: -331.05 | D21: 68 | E21: 33 | F21: =D21-E21 -> 35 | H21: AXIS BANK | I21: -1039.3 | J21: 70 | K21: 32 | L21: =J21-K21 -> 38
B22: KOTAKBANK | C22: -2041.05 | D22: 67 | E22: 26 | F22: =D22-E22 -> 41 | H22: KOTAKBANK | I22: 1527.84 | J22: 63 | K22: 37 | L22: =J22-K22 -> 26
B23: YES BANK | C23: -1496.67 | D23: 69 | E23: 24 | F23: =D23-E23 -> 45 | H23: YES BANK | I23: 1308.95 | J23: 71 | K23: 37 | L23: =J23-K23 -> 34
B24: AUB BANK | C24: -289.6 | D24: 71 | E24: 28 | F24: =D24-E24 -> 43 | H24: AUB BANK | I24: -635.55 | J24: 73 | K24: 30 | L24: =J24-K24 -> 43
B25: INDUSINDBK | C25: -3929.85 | D25: 71 | E25: 24 | F25: =D25-E25 -> 47 | H25: INDUSINDBK | I25: 3045.39 | J25: 78 | K25: 39 | L25: =J25-K25 -> 39
B26: ICICI BANK | C26: -580 | D26: 64 | E26: 31 | F26: =D26-E26 -> 33 | H26: ICICI BANK | I26: 1281.09 | J26: 63 | K26: 33 | L26: =J26-K26 -> 30
B27: IDFCFIRSTB | C27: -3079.19 | D27: 77 | E27: 27 | F27: =D27-E27 -> 50 | H27: IDFCFIRSTB | I27: 2362.21 | J27: 74 | K27: 41 | L27: =J27-K27 -> 33
B28: BANKBARODA | C28: -2184.34 | D28: 73 | E28: 28 | F28: =D28-E28 -> 45 | H28: BANKBARODA | I28: -52.1 | J28: 80 | K28: 37 | L28: =J28-K28 -> 43
B29: UNIONBANK | C29: -5101.72 | D29: 82 | E29: 25 | F29: =D29-E29 -> 57 | H29: UNIONBANK | I29: 5025.57 | J29: 73 | K29: 42 | L29: =J29-K29 -> 31
B30: FEDERAL BANK | C30: -2652.81 | D30: 68 | E30: 24 | F30: =D30-E30 -> 44 | H30: FEDERAL BANK | I30: 2761.73 | J30: 69 | K30: 43 | L30: =J30-K30 -> 26
D31: =SUM(D20:D30) -> 774 | E31: =SUM(E20:E30) -> 298 | F31: =SUM(F20:F30) -> 476 | J31: =SUM(J20:J30) -> 777 | K31: =SUM(K20:K30) -> 407 | L31: =SUM(L20:L30) -> 370
B32: Q3 | H32: Q3
B33: SYMBOL | C33: BACKTEST P&L | D33: TOTAL NUMBER OF TRADES | E33: NUMBER OF WINS | F33: NUMBER OF LOSSES | H33: SYMBOL | I33: BACKTEST P&L | J33: TOTAL NUMBER OF TRADES | K33: NUMBER OF WINS | L33: NUMBER OF LOSSES
B34: HDFC BANK | C34: 1608.95 | D34: 62 | E34: 32 | F34: =D34-E34 -> 30 | H34: HDFC BANK | I34: -1216.45 | J34: 66 | K34: 29 | L34: =J34-K34 -> 37
B35: AXIS BANK | C35: -361.64 | D35: 64 | E35: 29 | F35: =D35-E35 -> 35 | H35: AXIS BANK | I35: -251.3 | J35: 64 | K35: 31 | L35: =J35-K35 -> 33
B36: KOTAKBANK | C36: 1737.5 | D36: 64 | E36: 35 | F36: =D36-E36 -> 29 | H36: KOTAKBANK | I36: -511.59 | J36: 70 | K36: 33 | L36: =J36-K36 -> 37
B37: YES BANK | C37: -2227.84 | D37: 62 | E37: 23 | F37: =D37-E37 -> 39 | H37: YES BANK | I37: 879.58 | J37: 63 | K37: 34 | L37: =J37-K37 -> 29
B38: AUB BANK | C38: 3060.35 | D38: 73 | E38: 38 | F38: =D38-E38 -> 35 | H38: AUB BANK | I38: -2182.45 | J38: 73 | K38: 29 | L38: =J38-K38 -> 44
B39: INDUSINDBK | C39: 1904.3 | D39: 79 | E39: 37 | F39: =D39-E39 -> 42 | H39: INDUSINDBK | I39: -843.15 | J39: 76 | K39: 33 | L39: =J39-K39 -> 43
B40: ICICI BANK | C40: -181.14 | D40: 61 | E40: 31 | F40: =D40-E40 -> 30 | H40: ICICI BANK | I40: 208.84 | J40: 61 | K40: 34 | L40: =J40-K40 -> 27
B41: IDFCFIRSTB | C41: 1900.18 | D41: 70 | E41: 37 | F41: =D41-E41 -> 33 | H41: IDFCFIRSTB | I41: -1449.46 | J41: 81 | K41: 33 | L41: =J41-K41 -> 48
...

Sheet MA
B1: PRIVATE BANKS
B3: BUY | H3: SELL
B4: Q1 | H4: Q1
B5: Name | C5: Total P/L | D5: Trades | E5: Total Win | F5: Total Loss | H5: Name | I5: Total P/L | J5: Trades | K5: Total Win | L5: Total Loss
B6: AUBANK | C6: 1951.1 | D6: 21 | E6: 17 | F6: =D6+E6 -> 38 | H6: AUBANK | I6: -1838.3 | J6: 35 | K6: 13 | L6: =J6-K6 -> 22
B7: AXISBANK | C7: 34.8 | D7: 19 | E7: 23 | F7: =D7+E7 -> 42 | H7: AXISBANK | I7: 1169.89 | J7: 41 | K7: 22 | L7: =J7-K7 -> 19
B8: BANKBARODA | C8: 1029.84 | D8: 17 | E8: 23 | F8: =D8+E8 -> 40 | H8: BANKBARODA | I8: 828.72 | J8: 40 | K8: 18 | L8: =J8-K8 -> 22
B9: FEDERALBNK | C9: 1296.91 | D9: 24 | E9: 16 | F9: =D9+E9 -> 40 | H9: FEDERALBNK | I9: 250.24 | J9: 39 | K9: 16 | L9: =J9-K9 -> 23
B10: HDFCBANK | C10: 908 | D10: 22 | E10: 18 | F10: =D10+E10 -> 40 | H10: HDFCBANK | I10: -377.95 | J10: 38 | K10: 16 | L10: =J10-K10 -> 22
B11: ICICIBANK | C11: 495.25 | D11: 23 | E11: 12 | F11: =D11+E11 -> 35 | H11: ICICIBANK | I11: -431.85 | J11: 40 | K11: 17 | L11: =J11-K11 -> 23
B12: IDFCFIRSTB | C12: 532.7 | D12: 25 | E12: 19 | F12: =D12+E12 -> 44 | H12: IDFCFIRSTB | I12: -358.47 | J12: 41 | K12: 19 | L12: =J12-K12 -> 22
B13: INDUSINDBK | C13: 2644.9 | D13: 22 | E13: 19 | F13: =D13+E13 -> 41 | H13: INDUSINDBK | I13: -1586.85 | J13: 44 | K13: 17 | L13: =J13-K13 -> 27
B14: KOTAKBANK | C14: 841.94 | D14: 23 | E14: 15 | F14: =D14+E14 -> 38 | H14: KOTAKBANK | I14: -235.9 | J14: 40 | K14: 19 | L14: =J14-K14 -> 21
B15: UNIONBANK | C15: 240.74 | D15: 17 | E15: 23 | F15: =D15+E15 -> 40 | H15: UNIONBANK | I15: -538.9 | J15: 42 | K15: 17 | L15: =J15-K15 -> 25
B16: YESBANK | C16: -59.42 | D16: 16 | E16: 22 | F16: =D16+E16 -> 38 | H16: YESBANK | I16: 2273.37 | J16: 35 | K16: 27 | L16: =J16-K16 -> 8
D17: =SUM(D6:D16) -> 229 | E17: =SUM(E6:E16) -> 207 | F17: =SUM(F6:F16) -> 436 | J17: =SUM(J6:J16) -> 435 | K17: =SUM(K6:K16) -> 201 | L17: =SUM(L6:L16) -> 234
B18: Q2 | H18: Q2
B19: Name | C19: Total P/L | D19: Total Win | E19: Total Loss | F19: Trades | H19: Name | I19: Total P/L | J19: Trades | K19: Total Win | L19: Total Loss
B20: AUBANK | C20: -1705.94 | D20: 20 | E20: 24 | F20: =D20+E20 -> 44 | H20: AUBANK | I20: 2457.64 | J20: 45 | K20: 29 | L20: =J20-K20 -> 16
B21: AXISBANK | C21: -488.34 | D21: 20 | E21: 19 | F21: =D21+E21 -> 39 | H21: AXISBANK | I21: -348.19 | J21: 38 | K21: 20 | L21: =J21-K21 -> 18
B22: BANKBARODA | C22: -1009.32 | D22: 14 | E22: 26 | F22: =D22+E22 -> 40 | H22: BANKBARODA | I22: 2056.53 | J22: 43 | K22: 27 | L22: =J22-K22 -> 16
B23: FEDERALBNK | C23: -1070.86 | D23: 16 | E23: 25 | F23: =D23+E23 -> 41 | H23: FEDERALBNK | I23: 325.22 | J23: 46 | K23: 30 | L23: =J23-K23 -> 16
B24: HDFCBANK | C24: -591.44 | D24: 18 | E24: 24 | F24: =D24+E24 -> 42 | H24: HDFCBANK | I24: 927.29 | J24: 38 | K24: 25 | L24: =J24-K24 -> 13
B25: ICICIBANK | C25: -865.24 | D25: 19 | E25: 27 | F25: =D25+E25 -> 46 | H25: ICICIBANK | I25: -237.1 | J25: 44 | K25: 21 | L25: =J25-K25 -> 23
B26: IDFCFIRSTB | C26: -1346.1 | D26: 17 | E26: 27 | F26: =D26+E26 -> 44 | H26: IDFCFIRSTB | I26: 2400.66 | J26: 45 | K26: 26 | L26: =J26-K26 -> 19
B27: INDUSINDBK | C27: -102.04 | D27: 17 | E27: 25 | F27: =D27+E27 -> 42 | H27: INDUSINDBK | I27: 2760.34 | J27: 44 | K27: 26 | L27: =J27-K27 -> 18
B28: KOTAKBANK | C28: 121.75 | D28: 20 | E28: 22 | F28: =D28+E28 -> 42 | H28: KOTAKBANK | I28: 978.79 | J28: 39 | K28: 23 | L28: =J28-K28 -> 16
B29: UNIONBANK | C29: -926.95 | D29: 18 | E29: 25 | F29: =D29+E29 -> 43 | H29: UNIONBANK | I29: 805.88 | J29: 42 | K29: 21 | L29: =J29-K29 -> 21
B30: YESBANK | C30: 582.68 | D30: 23 | E30: 18 | F30: =D30+E30 -> 41 | H30: YESBANK | I30: 2175.81 | J30: 28 | K30: 13 | L30: =J30-K30 -> 15
D31: =SUM(D20:D30) -> 202 | E31: =SUM(E20:E30) -> 262 | F31: =SUM(F20:F30) -> 464 | J31: =SUM(J20:J30) -> 452 | K31: =SUM(K20:K30) -> 261 | L31: =SUM(L20:L30) -> 191
B32: Q3 | H32: Q3
B33: Name | C33: Total P/L | D33: Total Win | E33: Total Loss | F33: Trades | H33: Name | I33: Total P/L | J33: Trades | K33: Total Win | L33: Total Loss
B34: AUBANK | C34: 388.25 | D34: 20 | E34: 21 | F34: =D34+E34 -> 41 | H34: AUBANK | I34: -1193.65 | J34: 46 | K34: 18 | L34: =J34-K34 -> 28
B35: AXISBANK | C35: -858 | D35: 21 | E35: 25 | F35: =D35+E35 -> 46 | H35: AXISBANK | I35: -4.9 | J35: 47 | K35: 28 | L35: =J35-K35 -> 19
B36: BANKBARODA | C36: 1862.4 | D36: 21 | E36: 16 | F36: =D36+E36 -> 37 | H36: BANKBARODA | I36: 727.84 | J36: 37 | K36: 20 | L36: =J36-K36 -> 17
B37: FEDERALBNK | C37: 2298.97 | D37: 26 | E37: 11 | F37: =D37+E37 -> 37 | H37: FEDERALBNK | I37: -857.22 | J37: 39 | K37: 19 | L37: =J37-K37 -> 20
B38: HDFCBANK | C38: -644.49 | D38: 17 | E38: 24 | F38: =D38+E38 -> 41 | H38: HDFCBANK | I38: 779.7 | J38: 34 | K38: 19 | L38: =J38-K38 -> 15
B39: ICICIBANK | C39: 750.9 | D39: 23 | E39: 15 | F39: =D39+E39 -> 38 | H39: ICICIBANK | I39: -397.59 | J39: 35 | K39: 15 | L39: =J39-K39 -> 20
B40: IDFCFIRSTB | C40: 1262.58 | D40: 22 | E40: 16 | F40: =D40+E40 -> 38 | H40: IDFCFIRSTB | I40: 607.57 | J40: 40 | K40: 22 | L40: =J40-K40 -> 18
B41: INDUSINDBK | C41: -259.24 | D41: 19 | E41: 25 | F41: =D41+E41 -> 44 | H41: INDUSINDBK | I41: 1275.54 | J41: 41 | K41: 21 | L41: =J41-K41 -> 20
...

Sheet MACD
B1: PRIVATE BANKS
B3: BUY | H3: SELL
B4: Q1 | H4: Q1
B5: SYMBOL | C5: BACKTEST P&L | D5: TOTAL NUMBER OF TRADES | E5: NUMBER OF WINS | F5: NUMBER OF LOSSES | H5: SYMBOL | I5: BACKTEST P&L | J5: TOTAL NUMBER OF TRADES | K5: NUMBER OF WINS | L5: NUMBER OF LOSSES
B6: HDFC BANK | C6: 1403.2 | D6: 68 | E6: 36 | F6: 32 | H6: HDFC BANK | I6: 1050.34 | J6: 30 | K6: 15 | L6: =J6-K6 -> 15
B7: AXIS BANK | C7: -1930.09 | D7: 90 | E7: 34 | F7: 56 | H7: AXIS BANK | I7: -1655.25 | J7: 50 | K7: 17 | L7: =J7-K7 -> 33
B8: KOTAKBANK | C8: 1700.65 | D8: 79 | E8: 38 | F8: 41 | H8: KOTAKBANK | I8: 120.54 | J8: 42 | K8: 20 | L8: =J8-K8 -> 22
B9: YES BANK | C9: 1042.2 | D9: 94 | E9: 43 | F9: 51 | H9: YES BANK | I9: -1457.19 | J9: 48 | K9: 19 | L9: =J9-K9 -> 29
B10: AUB BANK | C10: 4040.95 | D10: 96 | E10: 49 | F10: 47 | H10: AUB BANK | I10: -3839.45 | J10: 55 | K10: 15 | L10: =J10-K10 -> 40
B11: INDUSINDBK | C11: 4425.1 | D11: 98 | E11: 52 | F11: 46 | H11: INDUSINDBK | I11: -3207.15 | J11: 70 | K11: 23 | L11: =J11-K11 -> 47
B12: ICICI BANK | C12: 523.25 | D12: 78 | E12: 42 | F12: 36 | H12: ICICI BANK | I12: -495.9 | J12: 29 | K12: 10 | L12: =J12-K12 -> 19
B13: IDFCFIRSTB | C13: 1431.09 | D13: 97 | E13: 42 | F13: 55 | H13: IDFCFIRSTB | I13: -5485.14 | J13: 69 | K13: 17 | L13: =J13-K13 -> 52
B14: BANKBARODA | C14: 2025.95 | D14: 95 | E14: 48 | F14: 47 | H14: BANKBARODA | I14: -1148.97 | J14: 50 | K14: 20 | L14: =J14-K14 -> 30
B15: UNIONBANK | C15: 1456.12 | D15: 101 | E15: 44 | F15: 57 | H15: UNIONBANK | I15: 38.39 | J15: 73 | K15: 28 | L15: =J15-K15 -> 45
B16: FEDERAL BANK | C16: 1502.07 | D16: 87 | E16: 47 | F16: 40 | H16: FEDERAL BANK | I16: 1501.5 | J16: 37 | K16: 21 | L16: =J16-K16 -> 16
D17: =SUM(D6:D16) -> 983 | E17: =SUM(E6:E16) -> 475 | F17: =SUM(F6:F16) -> 508 | J17: =SUM(J6:J16) -> 553 | K17: =SUM(K6:K16) -> 205 | L17: =SUM(L6:L16) -> 348
B18: Q2 | H18: Q2
B19: SYMBOL | C19: BACKTEST P&L | D19: TOTAL NUMBER OF TRADES | E19: NUMBER OF WINS | F19: NUMBER OF LOSSES | H19: SYMBOL | I19: BACKTEST P&L | J19: TOTAL NUMBER OF TRADES | K19: NUMBER OF WINS | L19: NUMBER OF LOSSES
B20: HDFC BANK | C20: -1287.69 | D20: 74 | E20: 34 | F20: 40 | H20: HDFC BANK | I20: 810.99 | J20: 68 | K20: 36 | L20: =J20-K20 -> 32
B21: AXIS BANK | C21: -805.85 | D21: 80 | E21: 39 | F21: 41 | H21: AXIS BANK | I21: -149.79 | J21: 83 | K21: 41 | L21: =J21-K21 -> 42
B22: KOTAKBANK | C22: -159.79 | D22: 77 | E22: 36 | F22: 41 | H22: KOTAKBANK | I22: 2403.04 | J22: 75 | K22: 45 | L22: =J22-K22 -> 30
B23: YES BANK | C23: -1674.86 | D23: 86 | E23: 33 | F23: 53 | H23: YES BANK | I23: 2695.14 | J23: 81 | K23: 46 | L23: =J23-K23 -> 35
B24: AUB BANK | C24: -702.54 | D24: 95 | E24: 38 | F24: 57 | H24: AUB BANK | I24: 3313.69 | J24: 96 | K24: 50 | L24: =J24-K24 -> 46
B25: INDUSINDBK | C25: -2794.04 | D25: 93 | E25: 33 | F25: 60 | H25: INDUSINDBK | I25: 5211.84 | J25: 93 | K25: 59 | L25: =J25-K25 -> 34
B26: ICICI BANK | C26: 34.65 | D26: 71 | E26: 33 | F26: 38 | H26: ICICI BANK | I26: 637.14 | J26: 66 | K26: 38 | L26: =J26-K26 -> 28
B27: IDFCFIRSTB | C27: -2237.37 | D27: 87 | E27: 33 | F27: 54 | H27: IDFCFIRSTB | I27: 2834.3 | J27: 77 | K27: 47 | L27: =J27-K27 -> 30
B28: BANKBARODA | C28: -696.19 | D28: 87 | E28: 36 | F28: 51 | H28: BANKBARODA | I28: 3159.7 | J28: 84 | K28: 49 | L28: =J28-K28 -> 35
B29: UNIONBANK | C29: -1565.12 | D29: 98 | E29: 38 | F29: 60 | H29: UNIONBANK | I29: 2804.68 | J29: 89 | K29: 45 | L29: =J29-K29 -> 44
B30: FEDERAL BANK | C30: -3072.62 | D30: 86 | E30: 29 | F30: 57 | H30: FEDERAL BANK | I30: 2998.48 | J30: 78 | K30: 46 | L30: =J30-K30 -> 32
D31: =SUM(D20:D30) -> 934 | E31: =SUM(E20:E30) -> 382 | F31: =SUM(F20:F30) -> 552 | J31: =SUM(J20:J30) -> 890 | K31: =SUM(K20:K30) -> 502 | L31: =SUM(L20:L30) -> 388
B32: Q3 | H32: Q3
B33: SYMBOL | C33: BACKTEST P&L | D33: TOTAL NUMBER OF TRADES | E33: NUMBER OF WINS | F33: NUMBER OF LOSSES | H33: SYMBOL | I33: BACKTEST P&L | J33: TOTAL NUMBER OF TRADES | K33: NUMBER OF WINS | L33: NUMBER OF LOSSES
B34: HDFC BANK | C34: 583.75 | D34: 71 | E34: 38 | F34: 33 | H34: HDFC BANK | I34: -700.4 | J34: 75 | K34: 33 | L34: =J34-K34 -> 42
B35: AXIS BANK | C35: -180.34 | D35: 73 | E35: 36 | F35: 37 | H35: AXIS BANK | I35: -455.2 | J35: 75 | K35: 36 | L35: =J35-K35 -> 39
B36: KOTAKBANK | C36: 743.1 | D36: 67 | E36: 33 | F36: 34 | H36: KOTAKBANK | I36: -332.6 | J36: 75 | K36: 42 | L36: =J36-K36 -> 33
B37: YES BANK | C37: -2610.19 | D37: 82 | E37: 35 | F37: 47 | H37: YES BANK | I37: 2013.63 | J37: 79 | K37: 44 | L37: =J37-K37 -> 35
B38: AUB BANK | C38: 2557.75 | D38: 76 | E38: 39 | F38: 37 | H38: AUB BANK | I38: -4123.5 | J38: 91 | K38: 36 | L38: =J38-K38 -> 55
B39: INDUSINDBK | C39: 977.9 | D39: 99 | E39: 45 | F39: 54 | H39: INDUSINDBK | I39: -776.7 | J39: 95 | K39: 43 | L39: =J39-K39 -> 52
B40: ICICI BANK | C40: 318.95 | D40: 65 | E40: 31 | F40: 34 | H40: ICICI BANK | I40: -810.15 | J40: 67 | K40: 29 | L40: =J40-K40 -> 38
B41: IDFCFIRSTB | C41: 129 | D41: 85 | E41: 38 | F41: 47 | H41: IDFCFIRSTB | I41: -1802.37 | J41: 84 | K41: 32 | L41: =J41-K41 -> 52
...

Sheet S_RSI
B1: PRIVATE BANKS
B3: BUY | H3: SELL
B4: Q1 | H4: Q1
B5: SYMBOL | C5: BACKTEST P&L | D5: TOTAL NUMBER OF TRADES | E5: NUMBER OF WINS | F5: NUMBER OF LOSSES | H5: SYMBOL | I5: BACKTEST P&L | J5: TOTAL NUMBER OF TRADES | K5: NUMBER OF WINS | L5: NUMBER OF LOSSES
B6: HDFC BANK | C6: -666.9 | D6: 29 | E6: 13 | F6: =D6-E6 -> 16 | H6: HDFC BANK | I6: -297.85 | J6: 47 | K6: 26 | L6: =J6-K6 -> 21
B7: AXIS BANK | C7: 1022.96 | D7: 41 | E7: 20 | F7: =D7-E7 -> 21 | H7: AXIS BANK | I7: 63.94 | J7: 50 | K7: 26 | L7: =J7-K7 -> 24
B8: KOTAKBANK | C8: 1037.6 | D8: 39 | E8: 20 | F8: =D8-E8 -> 19 | H8: KOTAKBANK | I8: 250.29 | J8: 40 | K8: 23 | L8: =J8-K8 -> 17
B9: YES BANK | C9: 44.98 | D9: 41 | E9: 16 | F9: =D9-E9 -> 25 | H9: YES BANK | I9: 304.58 | J9: 50 | K9: 21 | L9: =J9-K9 -> 29
B10: AUB BANK | C10: -327.45 | D10: 33 | E10: 12 | F10: =D10-E10 -> 21 | H10: AUB BANK | I10: -1483.1 | J10: 57 | K10: 24 | L10: =J10-K10 -> 33
B11: INDUSINDBK | C11: 233.6 | D11: 36 | E11: 14 | F11: =D11-E11 -> 22 | H11: INDUSINDBK | I11: 892.9 | J11: 49 | K11: 23 | L11: =J11-K11 -> 26
B12: ICICI BANK | C12: 267.25 | D12: 34 | E12: 18 | F12: =D12-E12 -> 16 | H12: ICICI BANK | I12: 285.45 | J12: 42 | K12: 24 | L12: =J12-K12 -> 18
B13: IDFCFIRSTB | C13: 606.15 | D13: 36 | E13: 19 | F13: =D13-E13 -> 17 | H13: IDFCFIRSTB | I13: -1019.94 | J13: 51 | K13: 24 | L13: =J13-K13 -> 27
B14: BANKBARODA | C14: -1191.36 | D14: 38 | E14: 15 | F14: =D14-E14 -> 23 | H14: BANKBARODA | I14: -486.61 | J14: 49 | K14: 21 | L14: =J14-K14 -> 28
B15: UNIONBANK | C15: 575.86 | D15: 37 | E15: 17 | F15: =D15-E15 -> 20 | H15: UNIONBANK | I15: -493.67 | J15: 58 | K15: 27 | L15: =J15-K15 -> 31
B16: FEDERAL BANK | C16: 734.6 | D16: 43 | E16: 21 | F16: =D16-E16 -> 22 | H16: FEDERAL BANK | I16: 581.93 | J16: 54 | K16: 27 | L16: =J16-K16 -> 27
D17: =SUM(D6:D16) -> 407 | E17: =SUM(E6:E16) -> 185 | F17: =SUM(F6:F16) -> 222 | J17: =SUM(J6:J16) -> 547 | K17: =SUM(K6:K16) -> 266 | L17: =SUM(L6:L16) -> 281
B18: Q2 | H18: Q2
B19: SYMBOL | C19: BACKTEST P&L | D19: TOTAL NUMBER OF TRADES | E19: NUMBER OF WINS | F19: NUMBER OF LOSSES | H19: SYMBOL | I19: BACKTEST P&L | J19: TOTAL NUMBER OF TRADES | K19: NUMBER OF WINS | L19: NUMBER OF LOSSES
B20: HDFC BANK | C20: -312.4 | D20: 39 | E20: 15 | F20: =D20-E20 -> 24 | H20: HDFC BANK | I20: 66.5 | J20: 31 | K20: 20 | L20: =J20-K20 -> 11
B21: AXIS BANK | C21: 90.35 | D21: 38 | E21: 21 | F21: =D21-E21 -> 17 | H21: AXIS BANK | I21: 986.35 | J21: 36 | K21: 22 | L21: =J21-K21 -> 14
B22: KOTAKBANK | C22: -470 | D22: 39 | E22: 17 | F22: =D22-E22 -> 22 | H22: KOTAKBANK | I22: 1345.65 | J22: 36 | K22: 22 | L22: =J22-K22 -> 14
B23: YES BANK | C23: 310.31 | D23: 40 | E23: 20 | F23: =D23-E23 -> 20 | H23: YES BANK | I23: 546.75 | J23: 47 | K23: 27 | L23: =J23-K23 -> 20
B24: AUB BANK | C24: -221.4 | D24: 56 | E24: 22 | F24: =D24-E24 -> 34 | H24: AUB BANK | I24: 243.15 | J24: 47 | K24: 21 | L24: =J24-K24 -> 26
B25: INDUSINDBK | C25: -854.15 | D25: 54 | E25: 20 | F25: =D25-E25 -> 34 | H25: INDUSINDBK | I25: 1451.05 | J25: 38 | K25: 22 | L25: =J25-K25 -> 16
B26: ICICI BANK | C26: 470.85 | D26: 37 | E26: 21 | F26: =D26-E26 -> 16 | H26: ICICI BANK | I26: 553.25 | J26: 32 | K26: 20 | L26: =J26-K26 -> 12
B27: IDFCFIRSTB | C27: -1052.69 | D27: 52 | E27: 19 | F27: =D27-E27 -> 33 | H27: IDFCFIRSTB | I27: 1408.1 | J27: 34 | K27: 19 | L27: =J27-K27 -> 15
B28: BANKBARODA | C28: -674.23 | D28: 45 | E28: 18 | F28: =D28-E28 -> 27 | H28: BANKBARODA | I28: -61.87 | J28: 52 | K28: 23 | L28: =J28-K28 -> 29
B29: UNIONBANK | C29: 334.65 | D29: 43 | E29: 19 | F29: =D29-E29 -> 24 | H29: UNIONBANK | I29: 26.13 | J29: 50 | K29: 19 | L29: =J29-K29 -> 31
B30: FEDERAL BANK | C30: -1622.52 | D30: 43 | E30: 14 | F30: =D30-E30 -> 29 | H30: FEDERAL BANK | I30: 227.4 | J30: 29 | K30: 17 | L30: =J30-K30 -> 12
D31: =SUM(D20:D30) -> 486 | E31: =SUM(E20:E30) -> 206 | F31: =SUM(F20:F30) -> 280 | J31: =SUM(J20:J30) -> 432 | K31: =SUM(K20:K30) -> 232 | L31: =SUM(L20:L30) -> 200
B32: Q3 | H32: Q3
B33: SYMBOL | C33: BACKTEST P&L | D33: TOTAL NUMBER OF TRADES | E33: NUMBER OF WINS | F33: NUMBER OF LOSSES | H33: SYMBOL | I33: BACKTEST P&L | J33: TOTAL NUMBER OF TRADES | K33: NUMBER OF WINS | L33: NUMBER OF LOSSES
B34: HDFC BANK | C34: 392.85 | D34: 33 | E34: 22 | F34: =D34-E34 -> 11 | H34: HDFC BANK | I34: 146.25 | J34: 34 | K34: 20 | L34: =J34-K34 -> 14
B35: AXIS BANK | C35: -499.04 | D35: 31 | E35: 15 | F35: =D35-E35 -> 16 | H35: AXIS BANK | I35: -277.5 | J35: 43 | K35: 22 | L35: =J35-K35 -> 21
B36: KOTAKBANK | C36: 520.7 | D36: 31 | E36: 13 | F36: =D36-E36 -> 18 | H36: KOTAKBANK | I36: 326.1 | J36: 43 | K36: 25 | L36: =J36-K36 -> 18
B37: YES BANK | C37: -1580.8 | D37: 49 | E37: 21 | F37: =D37-E37 -> 28 | H37: YES BANK | I37: 805.21 | J37: 41 | K37: 24 | L37: =J37-K37 -> 17
B38: AUB BANK | C38: 1157.35 | D38: 35 | E38: 19 | F38: =D38-E38 -> 16 | H38: AUB BANK | I38: -860.05 | J38: 53 | K38: 24 | L38: =J38-K38 -> 29
B39: INDUSINDBK | C39: 973.55 | D39: 38 | E39: 20 | F39: =D39-E39 -> 18 | H39: INDUSINDBK | I39: -1748.9 | J39: 47 | K39: 19 | L39: =J39-K39 -> 28
B40: ICICI BANK | C40: -902.29 | D40: 38 | E40: 19 | F40: =D40-E40 -> 19 | H40: ICICI BANK | I40: -1065.9 | J40: 31 | K40: 14 | L40: =J40-K40 -> 17
B41: IDFCFIRSTB | C41: 665.99 | D41: 33 | E41: 18 | F41: =D41-E41 -> 15 | H41: IDFCFIRSTB | I41: -1853.97 | J41: 49 | K41: 18 | L41: =J41-K41 -> 31
...

Sheet PP
B1: PRIVATE BANKS
B3: BUY | H3: SELL
B4: Q1 | H4: Q1
B5: SYMBOL | C5: BACKTEST P&L | D5: TOTAL NUMBER OF TRADES | E5: NUMBER OF WINS | F5: NUMBER OF LOSSES | H5: SYMBOL | I5: BACKTEST P&L | J5: TOTAL NUMBER OF TRADES | K5: NUMBER OF WINS | L5: NUMBER OF LOSSES
B6: HDFC BANK | C6: 318.7 | D6: 30 | E6: 15 | F6: =D6-E6 -> 15 | H6: HDFC BANK | I6: -660.05 | J6: 33 | K6: 13 | L6: =J6-K6 -> 20
B7: AXIS BANK | C7: 660.89 | D7: 27 | E7: 15 | F7: =D7-E7 -> 12 | H7: AXIS BANK | I7: 243.04 | J7: 25 | K7: 13 | L7: =J7-K7 -> 12
B8: KOTAKBANK | C8: 435.15 | D8: 23 | E8: 11 | F8: =D8-E8 -> 12 | H8: KOTAKBANK | I8: 325.59 | J8: 26 | K8: 14 | L8: =J8-K8 -> 12
B9: YES BANK | C9: -1407.67 | D9: 31 | E9: 10 | F9: =D9-E9 -> 21 | H9: YES BANK | I9: 707.44 | J9: 38 | K9: 18 | L9: =J9-K9 -> 20
B10: AUB BANK | C10: 1545.05 | D10: 32 | E10: 16 | F10: =D10-E10 -> 16 | H10: AUB BANK | I10: -1003.85 | J10: 33 | K10: 13 | L10: =J10-K10 -> 20
B11: INDUSINDBK | C11: 3204.25 | D11: 27 | E11: 18 | F11: =D11-E11 -> 9 | H11: INDUSINDBK | I11: -876.55 | J11: 30 | K11: 11 | L11: =J11-K11 -> 19
B12: ICICI BANK | C12: -414.89 | D12: 25 | E12: 12 | F12: =D12-E12 -> 13 | H12: ICICI BANK | I12: 374.44 | J12: 32 | K12: 15 | L12: =J12-K12 -> 17
B13: IDFCFIRSTB | C13: 853.69 | D13: 30 | E13: 17 | F13: =D13-E13 -> 13 | H13: IDFCFIRSTB | I13: 260.26 | J13: 35 | K13: 14 | L13: =J13-K13 -> 21
B14: BANKBARODA | C14: 522.43 | D14: 30 | E14: 15 | F14: =D14-E14 -> 15 | H14: BANKBARODA | I14: -834.35 | J14: 31 | K14: 11 | L14: =J14-K14 -> 20
B15: UNIONBANK | C15: 3018.61 | D15: 33 | E15: 20 | F15: =D15-E15 -> 13 | H15: UNIONBANK | I15: 351.62 | J15: 33 | K15: 14 | L15: =J15-K15 -> 19
B16: FEDERAL BANK | C16: 1071.49 | D16: 24 | E16: 13 | F16: =D16-E16 -> 11 | H16: FEDERAL BANK | I16: 1864.67 | J16: 31 | K16: 16 | L16: =J16-K16 -> 15
D17: =SUM(D6:D16) -> 312 | E17: =SUM(E6:E16) -> 162 | F17: =SUM(F6:F16) -> 150 | J17: =SUM(J6:J16) -> 347 | K17: =SUM(K6:K16) -> 152 | L17: =SUM(L6:L16) -> 195
B18: Q2 | H18: Q2
B19: SYMBOL | C19: BACKTEST P&L | D19: TOTAL NUMBER OF TRADES | E19: NUMBER OF WINS | F19: NUMBER OF LOSSES | H19: SYMBOL | I19: BACKTEST P&L | J19: TOTAL NUMBER OF TRADES | K19: NUMBER OF WINS | L19: NUMBER OF LOSSES
B20: HDFC BANK | C20: -471.65 | D20: 24 | E20: 9 | F20: =D20-E20 -> 15 | H20: HDFC BANK | I20: 477.79 | J20: 29 | K20: 14 | L20: =J20-K20 -> 15
B21: AXIS BANK | C21: -713.24 | D21: 26 | E21: 10 | F21: =D21-E21 -> 16 | H21: AXIS BANK | I21: 480.54 | J21: 27 | K21: 17 | L21: =J21-K21 -> 10
B22: KOTAKBANK | C22: -627.84 | D22: 21 | E22: 9 | F22: =D22-E22 -> 12 | H22: KOTAKBANK | I22: -792.7 | J22: 26 | K22: 10 | L22: =J22-K22 -> 16
B23: YES BANK | C23: -281.64 | D23: 24 | E23: 8 | F23: =D23-E23 -> 16 | H23: YES BANK | I23: 1156.95 | J23: 29 | K23: 20 | L23: =J23-K23 -> 9
B24: AUB BANK | C24: -1010.44 | D24: 25 | E24: 10 | F24: =D24-E24 -> 15 | H24: AUB BANK | I24: 55.09 | J24: 35 | K24: 15 | L24: =J24-K24 -> 20
B25: INDUSINDBK | C25: -1340.79 | D25: 26 | E25: 8 | F25: =D25-E25 -> 18 | H25: INDUSINDBK | I25: 1219.84 | J25: 31 | K25: 16 | L25: =J25-K25 -> 15
B26: ICICI BANK | C26: -352.84 | D26: 19 | E26: 7 | F26: =D26-E26 -> 12 | H26: ICICI BANK | I26: 524.75 | J26: 22 | K26: 11 | L26: =J26-K26 -> 11
B27: IDFCFIRSTB | C27: -933.79 | D27: 27 | E27: 9 | F27: =D27-E27 -> 18 | H27: IDFCFIRSTB | I27: 1553.96 | J27: 32 | K27: 18 | L27: =J27-K27 -> 14
B28: BANKBARODA | C28: 149.92 | D28: 32 | E28: 14 | F28: =D28-E28 -> 18 | H28: BANKBARODA | I28: -164.01 | J28: 32 | K28: 15 | L28: =J28-K28 -> 17
B29: UNIONBANK | C29: 84.64 | D29: 28 | E29: 11 | F29: =D29-E29 -> 17 | H29: UNIONBANK | I29: 1109.22 | J29: 32 | K29: 18 | L29: =J29-K29 -> 14
B30: FEDERAL BANK | C30: -993.95 | D30: 19 | E30: 6 | F30: =D30-E30 -> 13 | H30: FEDERAL BANK | I30: 87.88 | J30: 20 | K30: 11 | L30: =J30-K30 -> 9
D31: =SUM(D20:D30) -> 271 | E31: =SUM(E20:E30) -> 101 | F31: =SUM(F20:F30) -> 170 | J31: =SUM(J20:J30) -> 315 | K31: =SUM(K20:K30) -> 165 | L31: =SUM(L20:L30) -> 150
B32: Q3 | H32: Q3
B33: SYMBOL | C33: BACKTEST P&L | D33: TOTAL NUMBER OF TRADES | E33: NUMBER OF WINS | F33: NUMBER OF LOSSES | H33: SYMBOL | I33: BACKTEST P&L | J33: TOTAL NUMBER OF TRADES | K33: NUMBER OF WINS | L33: NUMBER OF LOSSES
B34: HDFC BANK | C34: -579.65 | D34: 25 | E34: 11 | F34: =D34-E34 -> 14 | H34: HDFC BANK | I34: -0.5 | J34: 33 | K34: 18 | L34: =J34-K34 -> 15
B35: AXIS BANK | C35: -513.64 | D35: 26 | E35: 12 | F35: =D35-E35 -> 14 | H35: AXIS BANK | I35: 252.54 | J35: 31 | K35: 15 | L35: =J35-K35 -> 16
B36: KOTAKBANK | C36: 355.3 | D36: 24 | E36: 11 | F36: =D36-E36 -> 13 | H36: KOTAKBANK | I36: -814.7 | J36: 30 | K36: 14 | L36: =J36-K36 -> 16
B37: YES BANK | C37: 435.83 | D37: 21 | E37: 11 | F37: =D37-E37 -> 10 | H37: YES BANK | I37: -622.82 | J37: 25 | K37: 9 | L37: =J37-K37 -> 16
B38: AUB BANK | C38: -18.39 | D38: 31 | E38: 14 | F38: =D38-E38 -> 17 | H38: AUB BANK | I38: -669.95 | J38: 32 | K38: 13 | L38: =J38-K38 -> 19
B39: INDUSINDBK | C39: 971.45 | D39: 28 | E39: 13 | F39: =D39-E39 -> 15 | H39: INDUSINDBK | I39: -1717.65 | J39: 34 | K39: 12 | L39: =J39-K39 -> 22
B40: ICICI BANK | C40: 764 | D40: 21 | E40: 13 | F40: =D40-E40 -> 8 | H40: ICICI BANK | I40: -315 | J40: 28 | K40: 16 | L40: =J40-K40 -> 12
B41: IDFCFIRSTB | C41: 1239.12 | D41: 30 | E41: 19 | F41: =D41-E41 -> 11 | H41: IDFCFIRSTB | I41: -2297.99 | J41: 36 | K41: 10 | L41: =J41-K41 -> 26
...

Sheet Boillenger
B1: PRIVATE BANKS
B3: BUY | H3: SELL
B4: Q1 | H4: Q1
B5: SYMBOL | C5: BACKTEST P&L | D5: TOTAL NUMBER OF TRADES | E5: NUMBER OF WINS | F5: NUMBER OF LOSSES | H5: SYMBOL | I5: BACKTEST P&L | J5: TOTAL NUMBER OF TRADES | K5: NUMBER OF WINS | L5: NUMBER OF LOSSES
B6: HDFC BANK | C6: 159.65 | D6: 58 | E6: 27 | F6: =D6-E6 -> 31 | H6: HDFC BANK | I6: -882.6 | J6: 66 | K6: 35 | L6: =J6-K6 -> 31
B7: AXIS BANK | C7: -21.04 | D7: 64 | E7: 28 | F7: =D7-E7 -> 36 | H7: AXIS BANK | I7: 1474.84 | J7: 69 | K7: 39 | L7: =J7-K7 -> 30
B8: KOTAKBANK | C8: -303.14 | D8: 60 | E8: 32 | F8: =D8-E8 -> 28 | H8: KOTAKBANK | I8: -1595.9 | J8: 61 | K8: 24 | L8: =J8-K8 -> 37
B9: YES BANK | C9: 2299.28 | D9: 75 | E9: 35 | F9: =D9-E9 -> 40 | H9: YES BANK | I9: -1618.4 | J9: 70 | K9: 30 | L9: =J9-K9 -> 40
B10: AUB BANK | C10: 2319.6 | D10: 57 | E10: 32 | F10: =D10-E10 -> 25 | H10: AUB BANK | I10: -2509.5 | J10: 77 | K10: 30 | L10: =J10-K10 -> 47
B11: INDUSINDBK | C11: 2829.4 | D11: 67 | E11: 38 | F11: =D11-E11 -> 29 | H11: INDUSINDBK | I11: -725.85 | J11: 85 | K11: 36 | L11: =J11-K11 -> 49
B12: ICICI BANK | C12: 1517.7 | D12: 56 | E12: 34 | F12: =D12-E12 -> 22 | H12: ICICI BANK | I12: -102.9 | J12: 66 | K12: 32 | L12: =J12-K12 -> 34
B13: IDFCFIRSTB | C13: 1063.42 | D13: 65 | E13: 31 | F13: =D13-E13 -> 34 | H13: IDFCFIRSTB | I13: -1952.77 | J13: 73 | K13: 31 | L13: =J13-K13 -> 42
B14: BANKBARODA | C14: 634.86 | D14: 64 | E14: 31 | F14: =D14-E14 -> 33 | H14: BANKBARODA | I14: -788.89 | J14: 77 | K14: 30 | L14: =J14-K14 -> 47
B15: UNIONBANK | C15: -628.59 | D15: 81 | E15: 38 | F15: =D15-E15 -> 43 | H15: UNIONBANK | I15: -2388.66 | J15: 84 | K15: 30 | L15: =J15-K15 -> 54
B16: FEDERAL BANK | C16: -236.19 | D16: 69 | E16: 36 | F16: =D16-E16 -> 33 | H16: FEDERAL BANK | I16: 456.73 | J16: 73 | K16: 34 | L16: =J16-K16 -> 39
D17: =SUM(D6:D16) -> 716 | E17: =SUM(E6:E16) -> 362 | F17: =SUM(F6:F16) -> 354 | J17: =SUM(J6:J16) -> 801 | K17: =SUM(K6:K16) -> 351 | L17: =SUM(L6:L16) -> 450
B18: Q2 | H18: Q2
B19: SYMBOL | C19: BACKTEST P&L | D19: TOTAL NUMBER OF TRADES | E19: NUMBER OF WINS | F19: NUMBER OF LOSSES | H19: SYMBOL | I19: BACKTEST P&L | J19: TOTAL NUMBER OF TRADES | K19: NUMBER OF WINS | L19: NUMBER OF LOSSES
B20: HDFC BANK | C20: 210.95 | D20: 65 | E20: 35 | F20: =D20-E20 -> 30 | H20: HDFC BANK | I20: 276.34 | J20: 56 | K20: 30 | L20: =J20-K20 -> 26
B21: AXIS BANK | C21: -366.4 | D21: 61 | E21: 29 | F21: =D21-E21 -> 32 | H21: AXIS BANK | I21: 1498.6 | J21: 65 | K21: 40 | L21: =J21-K21 -> 25
B22: KOTAKBANK | C22: -891.04 | D22: 69 | E22: 35 | F22: =D22-E22 -> 34 | H22: KOTAKBANK | I22: 782.29 | J22: 56 | K22: 32 | L22: =J22-K22 -> 24
B23: YES BANK | C23: -2482.21 | D23: 67 | E23: 24 | F23: =D23-E23 -> 43 | H23: YES BANK | I23: 1310.03 | J23: 66 | K23: 36 | L23: =J23-K23 -> 30
B24: AUB BANK | C24: -947.59 | D24: 81 | E24: 35 | F24: =D24-E24 -> 46 | H24: AUB BANK | I24: 266.19 | J24: 65 | K24: 29 | L24: =J24-K24 -> 36
B25: INDUSINDBK | C25: -2671.34 | D25: 78 | E25: 25 | F25: =D25-E25 -> 53 | H25: INDUSINDBK | I25: 3761.64 | J25: 67 | K25: 43 | L25: =J25-K25 -> 24
B26: ICICI BANK | C26: 342.1 | D26: 58 | E26: 29 | F26: =D26-E26 -> 29 | H26: ICICI BANK | I26: 955.79 | J26: 63 | K26: 34 | L26: =J26-K26 -> 29
B27: IDFCFIRSTB | C27: -1957.76 | D27: 65 | E27: 26 | F27: =D27-E27 -> 39 | H27: IDFCFIRSTB | I27: 1467.42 | J27: 67 | K27: 41 | L27: =J27-K27 -> 26
B28: BANKBARODA | C28: -2124.46 | D28: 67 | E28: 26 | F28: =D28-E28 -> 41 | H28: BANKBARODA | I28: 644 | J28: 68 | K28: 34 | L28: =J28-K28 -> 34
B29: UNIONBANK | C29: -1460.49 | D29: 70 | E29: 24 | F29: =D29-E29 -> 46 | H29: UNIONBANK | I29: 2833.88 | J29: 72 | K29: 38 | L29: =J29-K29 -> 34
B30: FEDERAL BANK | C30: -2276.07 | D30: 70 | E30: 28 | F30: =D30-E30 -> 42 | H30: FEDERAL BANK | I30: 2390.99 | J30: 61 | K30: 35 | L30: =J30-K30 -> 26
D31: =SUM(D20:D30) -> 751 | E31: =SUM(E20:E30) -> 316 | F31: =SUM(F20:F30) -> 435 | J31: =SUM(J20:J30) -> 706 | K31: =SUM(K20:K30) -> 392 | L31: =SUM(L20:L30) -> 314
B32: Q3 | H32: Q3
B33: SYMBOL | C33: BACKTEST P&L | D33: TOTAL NUMBER OF TRADES | E33: NUMBER OF WINS | F33: NUMBER OF LOSSES | H33: SYMBOL | I33: BACKTEST P&L | J33: TOTAL NUMBER OF TRADES | K33: NUMBER OF WINS | L33: NUMBER OF LOSSES
B34: HDFC BANK | C34: 331.75 | D34: 57 | E34: 32 | F34: =D34-E34 -> 25 | H34: HDFC BANK | I34: 377.84 | J34: 64 | K34: 38 | L34: =J34-K34 -> 26
B35: AXIS BANK | C35: 20 | D35: 58 | E35: 26 | F35: =D35-E35 -> 32 | H35: AXIS BANK | I35: 271.39 | J35: 60 | K35: 27 | L35: =J35-K35 -> 33
B36: KOTAKBANK | C36: 995.39 | D36: 61 | E36: 33 | F36: =D36-E36 -> 28 | H36: KOTAKBANK | I36: 966.7 | J36: 64 | K36: 38 | L36: =J36-K36 -> 26
B37: YES BANK | C37: -3984.33 | D37: 75 | E37: 27 | F37: =D37-E37 -> 48 | H37: YES BANK | I37: 1712.72 | J37: 65 | K37: 35 | L37: =J37-K37 -> 30
B38: AUB BANK | C38: 1390.2 | D38: 57 | E38: 33 | F38: =D38-E38 -> 24 | H38: AUB BANK | I38: -1509.5 | J38: 72 | K38: 33 | L38: =J38-K38 -> 39
B39: INDUSINDBK | C39: 469.25 | D39: 66 | E39: 30 | F39: =D39-E39 -> 36 | H39: INDUSINDBK | I39: -1567.45 | J39: 72 | K39: 32 | L39: =J39-K39 -> 40
B40: ICICI BANK | C40: 696.65 | D40: 63 | E40: 33 | F40: =D40-E40 -> 30 | H40: ICICI BANK | I40: -947.15 | J40: 56 | K40: 24 | L40: =J40-K40 -> 32
B41: IDFCFIRSTB | C41: -520.15 | D41: 60 | E41: 28 | F41: =D41-E41 -> 32 | H41: IDFCFIRSTB | I41: -241.24 | J41: 79 | K41: 40 | L41: =J41-K41 -> 39
...

Sheet AWESOME Alligator
B1: PRIVATE BANKS
B3: BUY | H3: SELL
B4: Q1 | H4: Q1
B5: SYMBOL | C5: BACKTEST P&L | D5: TOTAL NUMBER OF TRADES | E5: NUMBER OF WINS | F5: NUMBER OF LOSSES | H5: SYMBOL | I5: BACKTEST P&L | J5: TOTAL NUMBER OF TRADES | K5: NUMBER OF WINS | L5: NUMBER OF LOSSES
B6: HDFC BANK | C6: 1145 | D6: 63 | E6: 30 | F6: =D6-E6 -> 33 | H6: HDFC BANK | I6: -778.55 | J6: 67 | K6: 30 | L6: =J6-K6 -> 37
B7: AXIS BANK | C7: -439.64 | D7: 61 | E7: 32 | F7: =D7-E7 -> 29 | H7: AXIS BANK | I7: 716.99 | J7: 61 | K7: 31 | L7: =J7-K7 -> 30
B8: KOTAKBANK | C8: 667.85 | D8: 64 | E8: 34 | F8: =D8-E8 -> 30 | H8: KOTAKBANK | I8: -692.7 | J8: 63 | K8: 28 | L8: =J8-K8 -> 35
B9: YES BANK | C9: 407.07 | D9: 64 | E9: 27 | F9: =D9-E9 -> 37 | H9: YES BANK | I9: 1047.59 | J9: 66 | K9: 40 | L9: =J9-K9 -> 26
B10: AUB BANK | C10: 2000.45 | D10: 72 | E10: 41 | F10: =D10-E10 -> 31 | H10: AUB BANK | I10: -125.45 | J10: 72 | K10: 33 | L10: =J10-K10 -> 39
B11: INDUSINDBK | C11: 2444.65 | D11: 75 | E11: 40 | F11: =D11-E11 -> 35 | H11: INDUSINDBK | I11: -3183.75 | J11: 81 | K11: 29 | L11: =J11-K11 -> 52
B12: ICICI BANK | C12: 1212.85 | D12: 57 | E12: 35 | F12: =D12-E12 -> 22 | H12: ICICI BANK | I12: -1311.95 | J12: 62 | K12: 24 | L12: =J12-K12 -> 38
B13: IDFCFIRSTB | C13: 2513.36 | D13: 70 | E13: 36 | F13: =D13-E13 -> 34 | H13: IDFCFIRSTB | I13: -2069.15 | J13: 65 | K13: 27 | L13: =J13-K13 -> 38
B14: BANKBARODA | C14: 527.42 | D14: 75 | E14: 41 | F14: =D14-E14 -> 34 | H14: BANKBARODA | I14: -47.91 | J14: 73 | K14: 35 | L14: =J14-K14 -> 38
B15: UNIONBANK | C15: 597.1 | D15: 79 | E15: 38 | F15: =D15-E15 -> 41 | H15: UNIONBANK | I15: -439.59 | J15: 73 | K15: 34 | L15: =J15-K15 -> 39
B16: FEDERAL BANK | C16: 594.91 | D16: 69 | E16: 35 | F16: =D16-E16 -> 34 | H16: FEDERAL BANK | I16: -1092.67 | J16: 69 | K16: 29 | L16: =J16-K16 -> 40
D17: =SUM(D6:D16) -> 749 | E17: =SUM(E6:E16) -> 389 | F17: =SUM(F6:F16) -> 360 | J17: =SUM(J6:J16) -> 752 | K17: =SUM(K6:K16) -> 340 | L17: =SUM(L6:L16) -> 412
B18: Q2 | H18: Q2
B19: SYMBOL | C19: BACKTEST P&L | D19: TOTAL NUMBER OF TRADES | E19: NUMBER OF WINS | F19: NUMBER OF LOSSES | H19: SYMBOL | I19: BACKTEST P&L | J19: TOTAL NUMBER OF TRADES | K19: NUMBER OF WINS | L19: NUMBER OF LOSSES
B20: HDFC BANK | C20: -1905.44 | D20: 60 | E20: 24 | F20: =D20-E20 -> 36 | H20: HDFC BANK | I20: 432.3 | J20: 61 | K20: 30 | L20: =J20-K20 -> 31
B21: AXIS BANK | C21: 14.5 | D21: 62 | E21: 31 | F21: =D21-E21 -> 31 | H21: AXIS BANK | I21: 753.14 | J21: 69 | K21: 39 | L21: =J21-K21 -> 30
B22: KOTAKBANK | C22: -111.34 | D22: 66 | E22: 33 | F22: =D22-E22 -> 33 | H22: KOTAKBANK | I22: 691.99 | J22: 62 | K22: 31 | L22: =J22-K22 -> 31
B23: YES BANK | C23: -1481.8 | D23: 64 | E23: 24 | F23: =D23-E23 -> 40 | H23: YES BANK | I23: 2705 | J23: 66 | K23: 43 | L23: =J23-K23 -> 23
B24: AUB BANK | C24: 597.35 | D24: 67 | E24: 32 | F24: =D24-E24 -> 35 | H24: AUB BANK | I24: 1095.69 | J24: 70 | K24: 36 | L24: =J24-K24 -> 34
B25: INDUSINDBK | C25: -1133.04 | D25: 64 | E25: 25 | F25: =D25-E25 -> 39 | H25: INDUSINDBK | I25: 2737.89 | J25: 66 | K25: 41 | L25: =J25-K25 -> 25
B26: ICICI BANK | C26: -612.64 | D26: 67 | E26: 31 | F26: =D26-E26 -> 36 | H26: ICICI BANK | I26: 260.15 | J26: 58 | K26: 35 | L26: =J26-K26 -> 23
B27: IDFCFIRSTB | C27: -2008 | D27: 70 | E27: 23 | F27: =D27-E27 -> 47 | H27: IDFCFIRSTB | I27: 846.49 | J27: 65 | K27: 35 | L27: =J27-K27 -> 30
B28: BANKBARODA | C28: -1929.49 | D28: 68 | E28: 25 | F28: =D28-E28 -> 43 | H28: BANKBARODA | I28: 3424.62 | J28: 63 | K28: 42 | L28: =J28-K28 -> 21
B29: UNIONBANK | C29: -2188.04 | D29: 76 | E29: 32 | F29: =D29-E29 -> 44 | H29: UNIONBANK | I29: 471.44 | J29: 68 | K29: 37 | L29: =J29-K29 -> 31
B30: FEDERAL BANK | C30: -1272.45 | D30: 62 | E30: 20 | F30: =D30-E30 -> 42 | H30: FEDERAL BANK | I30: 2280.84 | J30: 61 | K30: 35 | L30: =J30-K30 -> 26
D31: =SUM(D20:D30) -> 726 | E31: =SUM(E20:E30) -> 300 | F31: =SUM(F20:F30) -> 426 | J31: =SUM(J20:J30) -> 709 | K31: =SUM(K20:K30) -> 404 | L31: =SUM(L20:L30) -> 305
B32: Q3 | H32: Q3
B33: SYMBOL | C33: BACKTEST P&L | D33: TOTAL NUMBER OF TRADES | E33: NUMBER OF WINS | F33: NUMBER OF LOSSES | H33: SYMBOL | I33: BACKTEST P&L | J33: TOTAL NUMBER OF TRADES | K33: NUMBER OF WINS | L33: NUMBER OF LOSSES
B34: HDFC BANK | C34: -885.64 | D34: 62 | E34: 25 | F34: =D34-E34 -> 37 | H34: HDFC BANK | I34: 38.09 | J34: 61 | K34: 32 | L34: =J34-K34 -> 29
B35: AXIS BANK | C35: -169.64 | D35: 62 | E35: 29 | F35: =D35-E35 -> 33 | H35: AXIS BANK | I35: 1745.94 | J35: 58 | K35: 36 | L35: =J35-K35 -> 22
B36: KOTAKBANK | C36: -522.99 | D36: 62 | E36: 29 | F36: =D36-E36 -> 33 | H36: KOTAKBANK | I36: 67.39 | J36: 60 | K36: 34 | L36: =J36-K36 -> 26
B37: YES BANK | C37: -582.28 | D37: 61 | E37: 30 | F37: =D37-E37 -> 31 | H37: YES BANK | I37: 262.84 | J37: 66 | K37: 33 | L37: =J37-K37 -> 33
B38: AUB BANK | C38: -404.89 | D38: 67 | E38: 29 | F38: =D38-E38 -> 38 | H38: AUB BANK | I38: -627.85 | J38: 58 | K38: 28 | L38: =J38-K38 -> 30
B39: INDUSINDBK | C39: -277.89 | D39: 71 | E39: 33 | F39: =D39-E39 -> 38 | H39: INDUSINDBK | I39: -260.7 | J39: 73 | K39: 36 | L39: =J39-K39 -> 37
B40: ICICI BANK | C40: 1093.55 | D40: 56 | E40: 27 | F40: =D40-E40 -> 29 | H40: ICICI BANK | I40: -1082 | J40: 57 | K40: 23 | L40: =J40-K40 -> 34
B41: IDFCFIRSTB | C41: 657.97 | D41: 64 | E41: 32 | F41: =D41-E41 -> 32 | H41: IDFCFIRSTB | I41: -1034.44 | J41: 67 | K41: 31 | L41: =J41-K41 -> 36
...

Sheet CP
B2: PRIVATE BANKS
B4: BUY | H4: SELL
B5: Q1 | H5: Q1
B6: SYMBOL | C6: BACKTEST P&L | D6: TOTAL NUMBER OF TRADES | E6: NUMBER OF WINS | F6: NUMBER OF LOSSES | H6: SYMBOL | I6: BACKTEST P&L | J6: TOTAL NUMBER OF TRADES | K6: NUMBER OF WINS | L6: NUMBER OF LOSSES
B7: HDFC BANK | C7: 2.19 | D7: 37 | E7: 37 | F7: =D7-E7 -> 0 | H7: HDFC BANK | I7: -201.65 | J7: 29 | K7: 13 | L7: =J7-K7 -> 16
B8: AXIS BANK | C8: 3.63 | D8: 54 | E8: 54 | F8: =D8-E8 -> 0 | H8: AXIS BANK | I8: 509.24 | J8: 34 | K8: 18 | L8: =J8-K8 -> 16
B9: KOTAKBANK | C9: 6.91 | D9: 42 | E9: 42 | F9: =D9-E9 -> 0 | H9: KOTAKBANK | I9: 581.94 | J9: 30 | K9: 17 | L9: 13
B10: YES BANK | C10: 91.4 | D10: 38 | E10: 24 | F10: =D10-E10 -> 14 | H10: YES BANK | I10: -401.11 | J10: 28 | K10: 13 | L10: =J10-K10 -> 15
B11: AUB BANK | C11: 6.18 | D11: 55 | E11: 55 | F11: =D11-E11 -> 0 | H11: AUB BANK | I11: -2912.2 | J11: 39 | K11: 10 | L11: =J11-K11 -> 29
B12: INDUSINDBK | C12: 5.45 | D12: 46 | E12: 46 | F12: =D12-E12 -> 0 | H12: INDUSINDBK | I12: -1234.9 | J12: 38 | K12: 16 | L12: =J12-K12 -> 22
B13: ICICI BANK | C13: 7.27 | D13: 54 | E13: 54 | F13: =D13-E13 -> 0 | H13: ICICI BANK | I13: -323.95 | J13: 34 | K13: 13 | L13: =J13-K13 -> 21
B14: IDFCFIRSTB | C14: 5.7 | D14: 41 | E14: 28 | F14: =D14-E14 -> 13 | H14: IDFCFIRSTB | I14: -623.48 | J14: 32 | K14: 13 | L14: =J14-K14 -> 19
B15: BANKBARODA | C15: -6.92 | D15: 46 | E15: 26 | F15: =D15-E15 -> 20 | H15: BANKBARODA | I15: -683.54 | J15: 37 | K15: 14 | L15: 23
B16: UNIONBANK | C16: 6.11 | D16: 52 | E16: 31 | F16: =D16-E16 -> 21 | H16: UNIONBANK | I16: 150.87 | J16: 36 | K16: 14 | L16: =J16-K16 -> 22
B17: FEDERAL BANK | C17: -16.26 | D17: 47 | E17: 27 | F17: =D17-E17 -> 20 | H17: FEDERAL BANK | I17: -997.82 | J17: 39 | K17: 15 | L17: =J17-K17 -> 24
D18: =SUM(D7:D17) -> 512 | E18: =SUM(E7:E17) -> 424 | F18: =SUM(F7:F17) -> 88 | J18: =SUM(J7:J17) -> 376 | K18: =SUM(K7:K17) -> 156 | L18: =SUM(L7:L17) -> 220
B19: Q2 | H19: Q2
B20: SYMBOL | C20: BACKTEST P&L | D20: TOTAL NUMBER OF TRADES | E20: NUMBER OF WINS | F20: NUMBER OF LOSSES | H20: SYMBOL | I20: BACKTEST P&L | J20: TOTAL NUMBER OF TRADES | K20: NUMBER OF WINS | L20: NUMBER OF LOSSES
B21: HDFC BANK | C21: -53.64 | D21: 32 | E21: 14 | F21: =D21-E21 -> 18 | H21: HDFC BANK | I21: 548.09 | J21: 29 | K21: 19 | L21: 9
B22: AXIS BANK | C22: -1033.95 | D22: 38 | E22: 16 | F22: =D22-E22 -> 22 | H22: AXIS BANK | I22: 62.7 | J22: 37 | K22: 21 | L22: =J22-K22 -> 16
B23: KOTAKBANK | C23: -717.09 | D23: 38 | E23: 14 | F23: =D23-E23 -> 24 | H23: KOTAKBANK | I23: 956.04 | J23: 32 | K23: 17 | L23: =J23-K23 -> 15
B24: YES BANK | C24: -1691.91 | D24: 32 | E24: 11 | F24: =D24-E24 -> 21 | H24: YES BANK | I24: 2010.34 | J24: 30 | K24: 19 | L24: =J24-K24 -> 11
B25: AUB BANK | C25: 17.5 | D25: 38 | E25: 18 | F25: =D25-E25 -> 20 | H25: AUB BANK | I25: 1105.94 | J25: 34 | K25: 17 | L25: =J25-K25 -> 17
B26: INDUSINDBK | C26: -1752.39 | D26: 38 | E26: 11 | F26: =D26-E26 -> 27 | H26: INDUSINDBK | I26: 2299.19 | J26: 41 | K26: 24 | L26: 17
B27: ICICI BANK | C27: -984.84 | D27: 34 | E27: 23 | F27: =D27-E27 -> 11 | H27: ICICI BANK | I27: 713.14 | J27: 35 | K27: 22 | L27: =J27-K27 -> 13
B28: IDFCFIRSTB | C28: -1249.8 | D28: 37 | E28: 14 | F28: =D28-E28 -> 23 | H28: IDFCFIRSTB | I28: 2792.28 | J28: 33 | K28: 23 | L28: =J28-K28 -> 10
B29: BANKBARODA | C29: 155.54 | D29: 33 | E29: 15 | F29: =D29-E29 -> 18 | H29: BANKBARODA | I29: 276.54 | J29: 33 | K29: 17 | L29: =J29-K29 -> 16
B30: UNIONBANK | C30: -1119.64 | D30: 42 | E30: 16 | F30: =D30-E30 -> 26 | H30: UNIONBANK | I30: -372.12 | J30: 42 | K30: 19 | L30: =J30-K30 -> 23
B31: FEDERAL BANK | C31: -1856.52 | D31: 37 | E31: 10 | F31: =D31-E31 -> 27 | H31: FEDERAL BANK | I31: 1252.45 | J31: 36 | K31: 21 | L31: =J31-K31 -> 15
D32: =SUM(D21:D31) -> 399 | E32: =SUM(E21:E31) -> 162 | F32: =SUM(F21:F31) -> 237 | J32: =SUM(J21:J31) -> 382 | K32: =SUM(K21:K31) -> 219 | L32: =SUM(L21:L31) -> 162
B33: Q3 | H33: Q3
B34: SYMBOL | C34: BACKTEST P&L | D34: TOTAL NUMBER OF TRADES | E34: NUMBER OF WINS | F34: NUMBER OF LOSSES | H34: SYMBOL | I34: BACKTEST P&L | J34: TOTAL NUMBER OF TRADES | K34: NUMBER OF WINS | L34: NUMBER OF LOSSES
B35: HDFC BANK | C35: -1029.54 | D35: 34 | E35: 18 | F35: =D35-E35 -> 16 | H35: HDFC BANK | I35: -947.3 | J35: 35 | K35: 15 | L35: =J35-K35 -> 20
B36: AXIS BANK | C36: -843.84 | D36: 30 | E36: 15 | F36: =D36-E36 -> 15 | H36: AXIS BANK | I36: 633.95 | J36: 30 | K36: 18 | L36: =J36-K36 -> 12
B37: KOTAKBANK | C37: 246.5 | D37: 31 | E37: 13 | F37: =D37-E37 -> 18 | H37: KOTAKBANK | I37: -597.64 | J37: 30 | K37: 18 | L37: =J37-K37 -> 12
B38: YES BANK | C38: -731.87 | D38: 29 | E38: 12 | F38: =D38-E38 -> 17 | H38: YES BANK | I38: 1295.94 | J38: 29 | K38: 18 | L38: =J38-K38 -> 11
B39: AUB BANK | C39: -799.54 | D39: 40 | E39: 15 | F39: 24 | H39: AUB BANK | I39: -901.5 | J39: 33 | K39: 13 | L39: =J39-K39 -> 20
B40: INDUSINDBK | C40: -380.04 | D40: 40 | E40: 18 | F40: 22 | H40: INDUSINDBK | I40: 97.84 | J40: 37 | K40: 19 | L40: =J40-K40 -> 18
B41: ICICI BANK | C41: 183.1 | D41: 31 | E41: 14 | F41: 16 | H41: ICICI BANK | I41: 112.69 | J41: 30 | K41: 13 | L41: 16
B42: IDFCFIRSTB | C42: 1400.18 | D42: 35 | E42: 21 | F42: 14 | H42: IDFCFIRSTB | I42: 40.26 | J42: 33 | K42: 16 | L42: 17
...

Sheet RESULT
A1: SR. NO. | B1: INDICATOR | C1: Probability of Win | D1: Probability of Loss | E1: Ranking
A2: 1 | B2: RSI | C2: =RSI!D62 -> 0.46507304 | D2: =RSI!D63 -> 0.53492696
A3: 2 | B3: Supertrend | C3: =Supertrend!D62 -> 0.49148308 | D3: =Supertrend!D63 -> 0.50851692
A4: 3 | B4: VWAP | C4: =VWAP!D62 -> 0.44175444 | D4: =VWAP!D63 -> 0.55824556
A5: 4 | B5: MA | C5: =MA!D62 -> 0.6842906 | D5: =MA!D63 -> 0.3157094
A6: 5 | B6: MACD | C6: =MACD!$D$62 -> 0.47766032 | D6: =MACD!$D$63 -> 0.52233968
A7: 6 | B7: S_RSI | C7: =S_RSI!D62 -> 0.46507304 | D7: =S_RSI!D63 -> 0.53492696
A8: 7 | B8: PP | C8: =PP!D62 -> 0.46100731 | D8: =PP!D63 -> 0.53899269
A9: 8 | B9: Boillenger | C9: =Boillenger!D62 -> 0.46713972 | D9: =Boillenger!D63 -> 0.53286028
A10: 9 | B10: Awesome Alligator | C10: ='AWESOME Alligator'!D62 -> 0.48288908 | D10: ='AWESOME Alligator'!D63 -> 0.51711092
A11: 10 | B11: CP | C11: =CP!D63 -> 0.53245923 | D11: =CP!D64 -> 0.46754077
